2024-06-12 12:29:06,571->website.logs.logger_config:ERROR:ProgrammingError -> (psycopg2.errors.DuplicateTable) relation "pet_breeds_breed_id_seq" already exists

[SQL: 
    CREATE SEQUENCE pet_breeds_breed_id_seq;
    ]
(Background on this error at: https://sqlalche.me/e/20/f405)
Traceback (most recent call last):
  File "/usr/local/lib/python3.10/site-packages/sqlalchemy/engine/base.py", line 1967, in _exec_single_context
    self.dialect.do_execute(
  File "/usr/local/lib/python3.10/site-packages/sqlalchemy/engine/default.py", line 924, in do_execute
    cursor.execute(statement, parameters)
psycopg2.errors.DuplicateTable: relation "pet_breeds_breed_id_seq" already exists


The above exception was the direct cause of the following exception:

Traceback (most recent call last):
  File "/app/premade.py", line 50, in <module>
    session.execute(sequence_command)
  File "/usr/local/lib/python3.10/site-packages/sqlalchemy/orm/session.py", line 2351, in execute
    return self._execute_internal(
  File "/usr/local/lib/python3.10/site-packages/sqlalchemy/orm/session.py", line 2245, in _execute_internal
    result = conn.execute(
  File "/usr/local/lib/python3.10/site-packages/sqlalchemy/engine/base.py", line 1418, in execute
    return meth(
  File "/usr/local/lib/python3.10/site-packages/sqlalchemy/sql/elements.py", line 515, in _execute_on_connection
    return connection._execute_clauseelement(
  File "/usr/local/lib/python3.10/site-packages/sqlalchemy/engine/base.py", line 1640, in _execute_clauseelement
    ret = self._execute_context(
  File "/usr/local/lib/python3.10/site-packages/sqlalchemy/engine/base.py", line 1846, in _execute_context
    return self._exec_single_context(
  File "/usr/local/lib/python3.10/site-packages/sqlalchemy/engine/base.py", line 1986, in _exec_single_context
    self._handle_dbapi_exception(
  File "/usr/local/lib/python3.10/site-packages/sqlalchemy/engine/base.py", line 2353, in _handle_dbapi_exception
    raise sqlalchemy_exception.with_traceback(exc_info[2]) from e
  File "/usr/local/lib/python3.10/site-packages/sqlalchemy/engine/base.py", line 1967, in _exec_single_context
    self.dialect.do_execute(
  File "/usr/local/lib/python3.10/site-packages/sqlalchemy/engine/default.py", line 924, in do_execute
    cursor.execute(statement, parameters)
sqlalchemy.exc.ProgrammingError: (psycopg2.errors.DuplicateTable) relation "pet_breeds_breed_id_seq" already exists

[SQL: 
    CREATE SEQUENCE pet_breeds_breed_id_seq;
    ]
(Background on this error at: https://sqlalche.me/e/20/f405)
